<?xml version="1.0" encoding="utf-8"?>
<!-- This URDF was automatically created by SolidWorks to URDF Exporter! Originally created by Stephen Brawner (brawner@gmail.com) 
     Commit Version: 1.6.0-1-g15f4949  Build Version: 1.6.7594.29634
     For more information, please see http://wiki.ros.org/sw_urdf_exporter -->
<robot
  name="d2c_robot_description">
  <link
    name="base_link">
    <inertial>
      <origin
        xyz="-0.011095 -0.010324 0.014633"
        rpy="0 0 0" />
      <mass
        value="0.087818" />
      <inertia
        ixx="4.193E-05"
        ixy="-2.3735E-06"
        ixz="2.1385E-06"
        iyy="2.6929E-05"
        iyz="1.8617E-06"
        izz="5.68E-05" />
    </inertial>
    <visual>
      <origin
        xyz="0 0 0"
        rpy="0 0 0" />
      <geometry>
        <mesh
          filename="package://d2c_robot_description/meshes/base_link.STL" />
      </geometry>
      <material
        name="">
        <color
          rgba="0.79216 0.81961 0.93333 1" />
      </material>
    </visual>
    <collision>
      <origin
        xyz="0 0 0"
        rpy="0 0 0" />
      <geometry>
        <mesh
          filename="package://d2c_robot_description/meshes/base_link.STL" />
      </geometry>
    </collision>
  </link>
  <link
    name="link1">
    <inertial>
      <origin
        xyz="0.0016907 -0.00029083 0.020821"
        rpy="0 0 0" />
      <mass
        value="0.084203" />
      <inertia
        ixx="3.5148E-05"
        ixy="2.5544E-07"
        ixz="3.0439E-07"
        iyy="2.1191E-05"
        iyz="-4.4082E-09"
        izz="3.1481E-05" />
    </inertial>
    <visual>
      <origin
        xyz="0 0 0"
        rpy="0 0 0" />
      <geometry>
        <mesh
          filename="package://d2c_robot_description/meshes/link1.STL" />
      </geometry>
      <material
        name="">
        <color
          rgba="0.79216 0.81961 0.93333 1" />
      </material>
    </visual>
    <collision>
      <origin
        xyz="0 0 0"
        rpy="0 0 0" />
      <geometry>
        <mesh
          filename="package://d2c_robot_description/meshes/link1.STL" />
      </geometry>
    </collision>
  </link>
  <joint
    name="joint1"
    type="revolute">
    <origin
      xyz="-0.016486 -0.0032999 0.0429"
      rpy="0 0 0" />
    <parent
      link="base_link" />
    <child
      link="link1" />
    <axis
      xyz="0 0 1" />
    <limit
      lower="3.14"
      upper="-3.14"
      effort="0"
      velocity="0" />
  </joint>
  <link
    name="link2">
    <inertial>
      <origin
        xyz="0.015137 0.0025994 0.097393"
        rpy="0 0 0" />
      <mass
        value="0.25649" />
      <inertia
        ixx="0.00086048"
        ixy="-2.5703E-07"
        ixz="-1.0049E-06"
        iyy="0.00085527"
        iyz="1.0286E-05"
        izz="5.3981E-05" />
    </inertial>
    <visual>
      <origin
        xyz="0 0 0"
        rpy="0 0 0" />
      <geometry>
        <mesh
          filename="package://d2c_robot_description/meshes/link2.STL" />
      </geometry>
      <material
        name="">
        <color
          rgba="0.79216 0.81961 0.93333 1" />
      </material>
    </visual>
    <collision>
      <origin
        xyz="0 0 0"
        rpy="0 0 0" />
      <geometry>
        <mesh
          filename="package://d2c_robot_description/meshes/link2.STL" />
      </geometry>
    </collision>
  </link>
  <joint
    name="joint2"
    type="revolute">
    <origin
      xyz="0.0254 -0.0125 0.02335"
      rpy="0 0 0" />
    <parent
      link="link1" />
    <child
      link="link2" />
    <axis
      xyz="1 0 0" />
    <limit
      lower="3.14"
      upper="-3.14"
      effort="0"
      velocity="0" />
  </joint>
  <link
    name="link3">
    <inertial>
      <origin
        xyz="-0.020349 0.085 -3.562E-05"
        rpy="0 0 0" />
      <mass
        value="0.073185" />
      <inertia
        ixx="0.0001408"
        ixy="2.7755E-09"
        ixz="-4.2596E-09"
        iyy="9.6002E-06"
        iyz="6.0832E-20"
        izz="0.00014425" />
    </inertial>
    <visual>
      <origin
        xyz="0 0 0"
        rpy="0 0 0" />
      <geometry>
        <mesh
          filename="package://d2c_robot_description/meshes/link3.STL" />
      </geometry>
      <material
        name="">
        <color
          rgba="0.79216 0.81961 0.93333 1" />
      </material>
    </visual>
    <collision>
      <origin
        xyz="0 0 0"
        rpy="0 0 0" />
      <geometry>
        <mesh
          filename="package://d2c_robot_description/meshes/link3.STL" />
      </geometry>
    </collision>
  </link>
  <joint
    name="joint3"
    type="revolute">
    <origin
      xyz="0.036 0.03025 0.18425"
      rpy="0 0 0" />
    <parent
      link="link2" />
    <child
      link="link3" />
    <axis
      xyz="1 0 0" />
    <limit
      lower="3.14"
      upper="-3.14"
      effort="0"
      velocity="0" />
  </joint>
  <link
    name="link4">
    <inertial>
      <origin
        xyz="0.013275 8.726E-05 -0.021127"
        rpy="0 0 0" />
      <mass
        value="0.05126" />
      <inertia
        ixx="2.4437E-05"
        ixy="5.2455E-09"
        ixz="-2.2472E-06"
        iyy="2.3336E-05"
        iyz="4.4082E-09"
        izz="3.0259E-05" />
    </inertial>
    <visual>
      <origin
        xyz="0 0 0"
        rpy="0 0 0" />
      <geometry>
        <mesh
          filename="package://d2c_robot_description/meshes/link4.STL" />
      </geometry>
      <material
        name="">
        <color
          rgba="0.79216 0.81961 0.93333 1" />
      </material>
    </visual>
    <collision>
      <origin
        xyz="0 0 0"
        rpy="0 0 0" />
      <geometry>
        <mesh
          filename="package://d2c_robot_description/meshes/link4.STL" />
      </geometry>
    </collision>
  </link>
  <joint
    name="joint4"
    type="revolute">
    <origin
      xyz="-0.0429 0.17 -6E-05"
      rpy="0 0 0" />
    <parent
      link="link3" />
    <child
      link="link4" />
    <axis
      xyz="-1 0 -0.0013953" />
    <limit
      lower="3.14"
      upper="-3.14"
      effort="0"
      velocity="0" />
  </joint>
</robot>
